<?xml version="1.0" encoding="utf-8"?>
<robot xmlns:xacro="http://www.ros.org/wiki/xacro" name="hand">
  <!-- safety_distance: Minimum safety distance in [m] by which the collision volumes are expanded and which is enforced during robot motions -->
  <xacro:macro name="hand" params="connected_to:='' ns:='' description_pkg:='franka_description' rpy:='0 0 0' xyz:='0 0 0.1' safety_distance:=0">
    <xacro:unless value="${connected_to == ''}">
      <joint name="${ns}_hand_joint" type="fixed">
        <parent link="${connected_to}"/>
        <child link="${ns}_hand"/>
        <origin xyz="${xyz}" rpy="${rpy}"/>
      </joint>
    </xacro:unless>
    <link name="${ns}_hand">
      <visual>
        <geometry>
          <mesh filename="package://${description_pkg}/meshes/visual/hand.dae"/>
        </geometry>
      </visual>
      <collision>
        <geometry>
          <mesh filename="package://${description_pkg}/meshes/collision/hand.stl"/>
        </geometry>
      </collision>
      <inertial>
        <origin xyz="-6.7624e-06 0.00152435 0.0275912" rpy="0 0 0"/>
        <mass value="0.14060765127978503"/>
        <inertia ixx="0.0001" ixy="0.000"  ixz="0.000"  
         iyy="0.0001" iyz="0.000"
         izz="0.0001" />
        <!--inertia ixx="0.0005365450414352072" iyy="7.70511954783727e-05" izz="0.0004938176882694914" ixy="1.7911952957732454e-08" ixz="-2.320071910601251e-08" iyz="4.681149945315967e-08"/-->
      </inertial>
    </link>
    <!-- Define the hand_tcp frame -->
    <link name="${ns}_hand_tcp"/>
    <joint name="${ns}_hand_tcp_joint" type="fixed">
      <origin xyz="0 0 0.1034" rpy="0 0 0"/>
      <parent link="${ns}_hand"/>
      <child link="${ns}_hand_tcp"/>
    </joint>
    <link name="${ns}_leftfinger">
      <visual>
        <geometry>
          <mesh filename="package://${description_pkg}/meshes/visual/finger.dae"/>
        </geometry>
      </visual>
      <collision>
        <geometry>
          <mesh filename="package://${description_pkg}/meshes/collision/finger.stl"/>
        </geometry>
      </collision>
      <inertial>
        <origin xyz="-6.2561e-06 0.00227781 -0.0277116" rpy="0 0 0"/>
        <mass value="0.2238453537819424"/>
        <inertia ixx="6.74804167363695e-05" iyy="6.627189221641395e-05" izz="1.550396267804825e-05" ixy="-4.1027443646025676e-09" ixz="1.8693673970152995e-08" iyz="1.1967548474390802e-05"/>
      </inertial>
    </link>
    <link name="${ns}_rightfinger">
      <visual>
        <origin xyz="0 0 0" rpy="0 0 ${pi}"/>
        <geometry>
          <mesh filename="package://${description_pkg}/meshes/visual/finger.dae"/>
        </geometry>
      </visual>
      <collision>
        <origin xyz="0 0 0" rpy="0 0 ${pi}"/>
        <geometry>
          <mesh filename="package://${description_pkg}/meshes/collision/finger.stl"/>
        </geometry>
      </collision>
      <inertial>
        <origin xyz="-6.2561e-06 0.00227781 -0.0277116" rpy="0 0 0"/>
        <mass value="0.2238453537819424"/>
        <inertia ixx="6.74804167363695e-05" iyy="6.627189221641395e-05" izz="1.550396267804825e-05" ixy="-4.1027443646025676e-09" ixz="1.8693673970152995e-08" iyz="1.1967548474390802e-05"/>
      </inertial>
    </link>
    <joint name="${ns}_finger_joint1" type="prismatic">
      <parent link="${ns}_hand"/>
      <child link="${ns}_leftfinger"/>
      <origin xyz="0 0 0.0584" rpy="0 0 0"/>
      <axis xyz="0 1 0"/>
      <limit effort="20" lower="0.0" upper="0.04" velocity="0.2"/>
      <dynamics damping="3.0" friction="0.546"/>
    </joint>
    <joint name="${ns}_finger_joint2" type="prismatic">
      <parent link="${ns}_hand"/>
      <child link="${ns}_rightfinger"/>
      <origin xyz="0 0 0.0584" rpy="0 0 0"/>
      <axis xyz="0 -1 0"/>
      <limit effort="20" lower="0.0" upper="0.04" velocity="0.2"/>
      <mimic joint="${ns}_finger_joint1"/>
      <dynamics damping="3.0" friction="0.546"/>
    </joint>
  </xacro:macro>
</robot>
