<?xml version='1.0' encoding='utf-8'?>
<robot xmlns:xacro="http://www.ros.org/wiki/xacro" name="panda">
  <!-- safety_distance: Minimum safety distance in [m] by which the collision volumes are expanded and which is enforced during robot motions -->
  <!-- arm_id: Namespace of the panda arm. Serves to differentiate between arms in case of multiple instances. -->
  <xacro:macro name="panda_arm" params="arm_id:='panda' description_pkg:='franka_description' connected_to:='' xyz:='0 0 0' rpy:='0 0 0' safety_distance:=0">
    <xacro:unless value="${not connected_to}">
      <joint name="${arm_id}_joint_${connected_to}" type="fixed">
        <parent link="${connected_to}"/>
        <child link="${arm_id}_link0"/>
        <origin rpy="${rpy}" xyz="${xyz}"/>
      </joint>
    </xacro:unless>

    <!-- for simulation -->
    <xacro:property name="joint_damping" value="5.0"/>
    <!-- end for simulation -->

    <link name="${arm_id}_link0">
      <visual>
        <geometry>
          <mesh filename="package://${description_pkg}/meshes/visual/link0.dae"/>
        </geometry>
      </visual>
      <collision>
        <geometry>
          <mesh filename="package://${description_pkg}/meshes/collision/link0.stl"/>
        </geometry>
      </collision>
      <!--for simulation -->
      <inertial>
        <origin xyz="-0.025566 -2.87883e-05 0.057332" rpy="0 0 0"/>
        <mass value="0.2814271300104062"/>
        <inertia ixx="0.0001" ixy="0.000"  ixz="0.000"  
         iyy="0.0001" iyz="0.000"
         izz="0.0001" />
        <!--inertia ixx="0.0075390636364814695" iyy="0.010508017427382959" izz="0.009864933638708275" ixy="-1.5053124574783335e-05" ixz="-0.0012144328835738973" iyz="1.0434803501032979e-05"/-->
      </inertial>
      <!--for simulation -->
    </link>

    <link name="${arm_id}_link1">
      <visual>
        <geometry>
          <mesh filename="package://${description_pkg}/meshes/visual/link1.dae"/>
        </geometry>
      </visual>
      <collision>
        <geometry>
          <mesh filename="package://${description_pkg}/meshes/collision/link1.stl"/>
        </geometry>
      </collision>
      <!-- for simulation -->
      <inertial>
        <origin xyz="-3.72212e-09 -0.0324958 -0.0675818" rpy="0 0 0"/>
        <mass value="0.26433170427227215"/>
        <inertia ixx="0.0001" ixy="0.000"  ixz="0.000"  
         iyy="0.0001" iyz="0.000"
         izz="0.0001" />
        <!--inertia ixx="0.017405076982879724" iyy="0.015352077935781732" izz="0.005987891663073857" ixy="-8.687986369621078e-09" ixz="1.6277819062920423e-08" iyz="0.004510855959102245"/-->
      </inertial>
      <!-- end for simulation -->
    </link>

    <joint name="${arm_id}_joint1" type="revolute">
      <safety_controller k_position="100.0" k_velocity="40.0" soft_lower_limit="-2.8973" soft_upper_limit="2.8973"/>
      <origin rpy="0 0 0" xyz="0 0 0.333"/>
      <parent link="${arm_id}_link0"/>
      <child link="${arm_id}_link1"/>
      <axis xyz="0 0 1"/>
      <limit effort="87" lower="-2.8973" upper="2.8973" velocity="2.1750"/>
      <!-- for simulation -->
      <dynamics damping="${joint_damping}" friction="0.546"/>
      <!-- end for simulation -->
    </joint>

    <link name="${arm_id}_link2">
      <visual>
        <geometry>
          <mesh filename="package://${description_pkg}/meshes/visual/link2.dae"/>
        </geometry>
      </visual>
      <collision>
        <geometry>
          <mesh filename="package://${description_pkg}/meshes/collision/link2.stl"/>
        </geometry>
      </collision>
      <!-- for simulation -->
      <inertial>
        <origin xyz="3.17833e-07 -0.06861 0.0322285" rpy="0 0 0"/>
        <mass value="0.26652755331661186"/>
        <inertia ixx="0.0001" ixy="0.000"  ixz="0.000"  
         iyy="0.0001" iyz="0.000"
         izz="0.0001" />
        <!--inertia ixx="0.01778694005635383" iyy="0.006044133867952844" izz="0.01571095500455695" ixy="8.70635625879119e-08" ixz="3.752072058394008e-08" iyz="-0.004599490295490376"/-->
      </inertial>
      <!-- end for simulation -->
    </link>

    <joint name="${arm_id}_joint2" type="revolute">
      <safety_controller k_position="100.0" k_velocity="40.0" soft_lower_limit="-1.7628" soft_upper_limit="1.7628"/>
      <origin rpy="${-pi/2} 0 0" xyz="0 0 0"/>
      <parent link="${arm_id}_link1"/>
      <child link="${arm_id}_link2"/>
      <axis xyz="0 0 1"/>
      <limit effort="87" lower="-1.7628" upper="1.7628" velocity="2.1750"/>
      <!-- for simulation -->
      <dynamics damping="${joint_damping}" friction="0.87224"/>
      <!-- end for simulation -->
    </joint>

    <link name="${arm_id}_link3">
      <visual>
        <geometry>
          <mesh filename="package://${description_pkg}/meshes/visual/link3.dae"/>
        </geometry>
      </visual>
      <collision>
        <geometry>
          <mesh filename="package://${description_pkg}/meshes/collision/link3.stl"/>
        </geometry>
      </collision>
      <!-- for simulation -->
      <inertial>
        <origin xyz="0.0469893 0.0316374 -0.031704" rpy="0 0 0"/>
        <mass value="0.23293714829045733"/>
        <inertia ixx="0.0001" ixy="0.000"  ixz="0.000"  
         iyy="0.0001" iyz="0.000"
         izz="0.0001" />
        <!--inertia ixx="0.0075496764161139766" iyy="0.009680676080191398" izz="0.007944557422008086" ixy="-0.0024320464513492225" ixz="-0.003250815048103007" iyz="-0.0021316282421730694"/-->
      </inertial>
      <!-- end for simulation -->
    </link>

    <joint name="${arm_id}_joint3" type="revolute">
      <safety_controller k_position="100.0" k_velocity="40.0" soft_lower_limit="-2.8973" soft_upper_limit="2.8973"/>
      <origin rpy="${pi/2} 0 0" xyz="0 -0.316 0"/>
      <parent link="${arm_id}_link2"/>
      <child link="${arm_id}_link3"/>
      <axis xyz="0 0 1"/>
      <limit effort="87" lower="-2.8973" upper="2.8973" velocity="2.1750"/>
      <!-- for simulation -->
      <dynamics damping="${joint_damping}" friction="0.6406"/>
      <!-- end for simulation -->
    </joint>
    
    <link name="${arm_id}_link4">
      <visual>
        <geometry>
          <mesh filename="package://${description_pkg}/meshes/visual/link4.dae"/>
        </geometry>
      </visual>
      <collision>
        <geometry>
          <mesh filename="package://${description_pkg}/meshes/collision/link4.stl"/>
        </geometry>
      </collision>
      <!-- for simulation -->
      <inertial>
        <origin xyz="-0.0360505 0.0337069 0.0319019" rpy="0 0 0"/>
        <mass value="0.23104763646281508"/>
        <inertia ixx="0.0001" ixy="0.000"  ixz="0.000"  
         iyy="0.0001" iyz="0.000"
         izz="0.0001" />
        <!--inertia ixx="0.007764568814864828" iyy="0.008015776929980149" izz="0.009955882308071066" ixy="0.003371475204045935" ixz="-0.002343621113168248" iyz="0.0022917526161470624"/-->
      </inertial>
      <!-- end for simulation -->
    </link>
    
    <joint name="${arm_id}_joint4" type="revolute">
      <safety_controller k_position="100.0" k_velocity="40.0" soft_lower_limit="-3.0718" soft_upper_limit="-0.0698"/>
      <origin rpy="${pi/2} 0 0" xyz="0.0825 0 0"/>
      <parent link="${arm_id}_link3"/>
      <child link="${arm_id}_link4"/>
      <axis xyz="0 0 1"/>
      <limit effort="87" lower="-3.0718" upper="-0.0698" velocity="2.1750"/>
      <!-- for simulation -->
      <dynamics damping="${joint_damping}" friction="1.2794"/>
      <!-- end for simulation -->
    </joint>

    <link name="${arm_id}_link5">
      <visual>
        <geometry>
          <mesh filename="package://${description_pkg}/meshes/visual/link5.dae"/>
        </geometry>
      </visual>
      <collision>
        <geometry>
          <mesh filename="package://${description_pkg}/meshes/collision/link5.stl"/>
        </geometry>
      </collision>
      <!-- for simulation -->
      <inertial>
        <origin xyz="-6.12525e-06 0.0610427 -0.104176" rpy="0 0 0"/>
        <mass value="0.26226426154892004"/>
        <inertia ixx="0.0001" ixy="0.000"  ixz="0.000"  
         iyy="0.0001" iyz="0.000"
         izz="0.0001" />
        <!--inertia ixx="0.029070538014399377" iyy="0.027638529986528795" izz="0.004251111234400737" ixy="6.208738268725568e-07" ixz="-1.0059151925023392e-05" iyz="-0.007424306477850814"/-->
      </inertial>
      <!-- end for simulation -->
    </link>

    <joint name="${arm_id}_joint5" type="revolute">
      <safety_controller k_position="100.0" k_velocity="40.0" soft_lower_limit="-2.8973" soft_upper_limit="2.8973"/>
      <origin rpy="${-pi/2} 0 0" xyz="-0.0825 0.384 0"/>
      <parent link="${arm_id}_link4"/>
      <child link="${arm_id}_link5"/>
      <axis xyz="0 0 1"/>
      <limit effort="12" lower="-2.8973" upper="2.8973" velocity="2.6100"/>
      <!-- for simulation -->
      <dynamics damping="3.0" friction="0.839"/>
      <!-- end for simulation -->
    </joint>

    <link name="${arm_id}_link6">
      <visual>
        <geometry>
          <mesh filename="package://${description_pkg}/meshes/visual/link6.dae"/>
        </geometry>
      </visual>
      <collision>
        <geometry>
          <mesh filename="package://${description_pkg}/meshes/collision/link6.stl"/>
        </geometry>
      </collision>
      <!-- for simulation -->
      <inertial>
        <origin xyz="0.051051 0.00910797 0.0106343" rpy="0 0 0"/>
        <mass value="0.15025804886626795"/>
        <inertia ixx="0.0001" ixy="0.000"  ixz="0.000"  
         iyy="0.0001" iyz="0.000"
         izz="0.0001" />
        <!--inertia ixx="0.002940555801469018" iyy="0.00392105201248677" izz="0.0054115603870960195" ixy="-0.00042391108351381507" ixz="0.000610007735338717" iyz="0.00012647545430836214"/-->
      </inertial>
      <!-- end for simulation -->
    </link>
    
    <joint name="${arm_id}_joint6" type="revolute">
      <safety_controller k_position="100.0" k_velocity="40.0" soft_lower_limit="-0.0175" soft_upper_limit="3.7525"/>
      <origin rpy="${pi/2} 0 0" xyz="0 0 0"/>
      <parent link="${arm_id}_link5"/>
      <child link="${arm_id}_link6"/>
      <axis xyz="0 0 1"/>
      <limit effort="12" lower="-0.0175" upper="3.7525" velocity="2.6100"/>
      <!-- for simulation -->
      <dynamics damping="3.0" friction="0.303"/>
      <!-- end for simulation -->
    </joint>
    
    <link name="${arm_id}_link7">
      <visual>
        <geometry>
          <mesh filename="package://${description_pkg}/meshes/visual/link7.dae"/>
        </geometry>
      </visual>
      <collision>
        <geometry>
          <mesh filename="package://${description_pkg}/meshes/collision/link7.stl"/>
        </geometry>
      </collision>
      <!-- for simulation -->
      <inertial>
        <origin xyz="0.0109695 0.0107965 0.0650412" rpy="0 0 0"/>
        <mass value="0.05237668134788256"/>
        <!--inertia ixx="0.00001" ixy="0.000"  ixz="0.000"  
         iyy="0.00001" iyz="0.000"
         izz="0.00001" /-->
        <inertia ixx="0.0008621467959726535" iyy="0.0008613100184801048" izz="0.0009961139396618219" ixy="-0.000011871071570425467" ixz="3.866602604509339e-06" iyz="-9.057841649422724e-06"/>
      </inertial>
      <!-- end for simulation -->
    </link>

    <joint name="${arm_id}_joint7" type="revolute">
      <!--safety_controller k_position="100.0" k_velocity="40.0" soft_lower_limit="-2.8973" soft_upper_limit="2.8973"/-->
      <origin rpy="${pi/2} 0 0" xyz="0.088 0 0"/>
      <parent link="${arm_id}_link6"/>
      <child link="${arm_id}_link7"/>
      <axis xyz="0 0 1"/>
      <limit effort="12" lower="-2.8973" upper="2.8973" velocity="2.6100"/>
      <!-- for simulation -->
      <dynamics damping="3.0" friction="0.05649"/>
      <!-- end for simulation -->
    </joint>

  </xacro:macro>
</robot>
